Workbook

Sheet License & Disclaimer
A1: License & Disclaimer
A2: License | B2: Apache License 2.0 - https://www.apache.org/licenses/LICENSE-2.0
A3: Copyright | B3: Copyright 2026 Mayank
A4: Version | B4: 0.1.0 (2026-10-21)
A5: Disclaimer | B5: Not legal or audit advice. Requirement text is a condensed paraphrase; verify against the authoritative source. CIA classifications, domain groupings and cross-framework mappings are expert judgement. Provided AS IS. Standards referenced remain the property of their publishers; see NOTICE and DISCLAIMER.md.
A6: OWASP LLM Top 10 | B6: (c) OWASP Foundation, CC BY-SA 4.0; paraphrased, attribution required.
A7: MITRE ATLAS | B7: (c) The MITRE Corporation; Apache-2.0.
A8: ISO/IEC | B8: (c) ISO/IEC; referenced by clause number and paraphrased only.
A9: Examples | B9: Rows with Row ID 'EX-*' in tab 19 are fictional examples.

Sheet Summary
A1: Compliance Summary
A3: Group | B3: Total items | C3: Not started | D3: In progress | E3: Implemented | F3: Verified | G3: Not applicable | H3: % Complete (Impl.+Verified / applicable)
A4: CIA-security: Clauses 4-10 | B4: =SUM(C4:G4) -> 5 | C4: =COUNTIFS('1 CIA-Security Controls'!$L$4:$L$23,"Not started",'1 CIA-Security Controls'!$B$4:$B$23,"Clause") -> 5 | D4: =COUNTIFS('1 CIA-Security Controls'!$L$4:$L$23,"In progress",'1 CIA-Security Controls'!$B$4:$B$23,"Clause") -> 0 | E4: =COUNTIFS('1 CIA-Security Controls'!$L$4:$L$23,"Implemented",'1 CIA-Security Controls'!$B$4:$B$23,"Clause") -> 0 | F4: =COUNTIFS('1 CIA-Security Controls'!$L$4:$L$23,"Verified",'1 CIA-Security Controls'!$B$4:$B$23,"Clause") -> 0 | G4: =COUNTIFS('1 CIA-Security Controls'!$L$4:$L$23,"Not applicable",'1 CIA-Security Controls'!$B$4:$B$23,"Clause") -> 0 | H4: =IFERROR((E4+F4)/(B4-G4),0) -> 0
A5: CIA-security: Annex A | B5: =SUM(C5:G5) -> 13 | C5: =COUNTIFS('1 CIA-Security Controls'!$L$4:$L$23,"Not started",'1 CIA-Security Controls'!$B$4:$B$23,"Annex A") -> 13 | D5: =COUNTIFS('1 CIA-Security Controls'!$L$4:$L$23,"In progress",'1 CIA-Security Controls'!$B$4:$B$23,"Annex A") -> 0 | E5: =COUNTIFS('1 CIA-Security Controls'!$L$4:$L$23,"Implemented",'1 CIA-Security Controls'!$B$4:$B$23,"Annex A") -> 0 | F5: =COUNTIFS('1 CIA-Security Controls'!$L$4:$L$23,"Verified",'1 CIA-Security Controls'!$B$4:$B$23,"Annex A") -> 0 | G5: =COUNTIFS('1 CIA-Security Controls'!$L$4:$L$23,"Not applicable",'1 CIA-Security Controls'!$B$4:$B$23,"Annex A") -> 0 | H5: =IFERROR((E5+F5)/(B5-G5),0) -> 0
A6: CIA-security TOTAL | B6: =B4+B5 -> 18 | C6: =C4+C5 -> 18 | D6: =D4+D5 -> 0 | E6: =E4+E5 -> 0 | F6: =F4+F5 -> 0 | G6: =G4+G5 -> 0 | H6: =IFERROR((E6+F6)/(B6-G6),0) -> 0
A7: Non-CIA: Clauses 4-10 | B7: =SUM(C7:G7) -> 27 | C7: =COUNTIFS('2 Non-CIA (Other) Controls'!$I$4:$I$57,"Not started",'2 Non-CIA (Other) Controls'!$B$4:$B$57,"Clause") -> 27 | D7: =COUNTIFS('2 Non-CIA (Other) Controls'!$I$4:$I$57,"In progress",'2 Non-CIA (Other) Controls'!$B$4:$B$57,"Clause") -> 0 | E7: =COUNTIFS('2 Non-CIA (Other) Controls'!$I$4:$I$57,"Implemented",'2 Non-CIA (Other) Controls'!$B$4:$B$57,"Clause") -> 0 | F7: =COUNTIFS('2 Non-CIA (Other) Controls'!$I$4:$I$57,"Verified",'2 Non-CIA (Other) Controls'!$B$4:$B$57,"Clause") -> 0 | G7: =COUNTIFS('2 Non-CIA (Other) Controls'!$I$4:$I$57,"Not applicable",'2 Non-CIA (Other) Controls'!$B$4:$B$57,"Clause") -> 0 | H7: =IFERROR((E7+F7)/(B7-G7),0) -> 0
A8: Non-CIA: Annex A | B8: =SUM(C8:G8) -> 25 | C8: =COUNTIFS('2 Non-CIA (Other) Controls'!$I$4:$I$57,"Not started",'2 Non-CIA (Other) Controls'!$B$4:$B$57,"Annex A") -> 25 | D8: =COUNTIFS('2 Non-CIA (Other) Controls'!$I$4:$I$57,"In progress",'2 Non-CIA (Other) Controls'!$B$4:$B$57,"Annex A") -> 0 | E8: =COUNTIFS('2 Non-CIA (Other) Controls'!$I$4:$I$57,"Implemented",'2 Non-CIA (Other) Controls'!$B$4:$B$57,"Annex A") -> 0 | F8: =COUNTIFS('2 Non-CIA (Other) Controls'!$I$4:$I$57,"Verified",'2 Non-CIA (Other) Controls'!$B$4:$B$57,"Annex A") -> 0 | G8: =COUNTIFS('2 Non-CIA (Other) Controls'!$I$4:$I$57,"Not applicable",'2 Non-CIA (Other) Controls'!$B$4:$B$57,"Annex A") -> 0 | H8: =IFERROR((E8+F8)/(B8-G8),0) -> 0
A9: Non-CIA TOTAL | B9: =B7+B8 -> 52 | C9: =C7+C8 -> 52 | D9: =D7+D8 -> 0 | E9: =E7+E8 -> 0 | F9: =F7+F8 -> 0 | G9: =G7+G8 -> 0 | H9: =IFERROR((E9+F9)/(B9-G9),0) -> 0
A10: OVERALL | B10: =B6+B9 -> 70 | C10: =C6+C9 -> 70 | D10: =D6+D9 -> 0 | E10: =E6+E9 -> 0 | F10: =F6+F9 -> 0 | G10: =G6+G9 -> 0 | H10: =IFERROR((E10+F10)/(B10-G10),0) -> 0
A12: CIA coverage of the CIA-security items | B12: Count
A13: Confidentiality (C) | B13: =COUNTIF('1 CIA-Security Controls'!$E$4:$E$23,"●") -> 15
A14: Integrity (I) | B14: =COUNTIF('1 CIA-Security Controls'!$F$4:$F$23,"●") -> 18
A15: Availability (A) | B15: =COUNTIF('1 CIA-Security Controls'!$G$4:$G$23,"●") -> 15
A16: All three (C+I+A) | B16: =COUNTIFS('1 CIA-Security Controls'!$E$4:$E$23,"●",'1 CIA-Security Controls'!$F$4:$F$23,"●",'1 CIA-Security Controls'!$G$4:$G$23,"●") -> 14
A18: EU AI Act
A19: Group | B19: Total items | C19: Not started | D19: In progress | E19: Implemented | F19: Verified | G19: Not applicable | H19: % Complete (Impl.+Verified / applicable)
A20: EU AI Act - all items | B20: =SUM(C20:G20) -> 34 | C20: =COUNTIF('3 EU AI Act'!$K$14:$K$56,"Not started") -> 34 | D20: =COUNTIF('3 EU AI Act'!$K$14:$K$56,"In progress") -> 0 | E20: =COUNTIF('3 EU AI Act'!$K$14:$K$56,"Implemented") -> 0 | F20: =COUNTIF('3 EU AI Act'!$K$14:$K$56,"Verified") -> 0 | G20: =COUNTIF('3 EU AI Act'!$K$14:$K$56,"Not applicable") -> 0 | H20: =IFERROR((E20+F20)/(B20-G20),0) -> 0
A21: EU AI Act - CIA-security items | B21: =SUMPRODUCT(--(( '3 EU AI Act'!E14:E56<>"")+('3 EU AI Act'!F14:F56<>"")+('3 EU AI Act'!G14:G56<>"")>0)) -> 12
A23: OECD AI Principles
A24: Group | B24: Total items | C24: Not started | D24: In progress | E24: Implemented | F24: Verified | G24: Not applicable | H24: % Complete (Impl.+Verified / applicable)
A25: OECD - all items | B25: =SUM(C25:G25) -> 14 | C25: =COUNTIF('4 OECD AI Principles'!$J$4:$J$20,"Not started") -> 14 | D25: =COUNTIF('4 OECD AI Principles'!$J$4:$J$20,"In progress") -> 0 | E25: =COUNTIF('4 OECD AI Principles'!$J$4:$J$20,"Implemented") -> 0 | F25: =COUNTIF('4 OECD AI Principles'!$J$4:$J$20,"Verified") -> 0 | G25: =COUNTIF('4 OECD AI Principles'!$J$4:$J$20,"Not applicable") -> 0 | H25: =IFERROR((E25+F25)/(B25-G25),0) -> 0
A26: OECD - CIA-security items | B26: =SUMPRODUCT(--(('4 OECD AI Principles'!D4:D20<>"")+('4 OECD AI Principles'!E4:E20<>"")+('4 OECD AI Principles'!F4:F20<>"")>0)) -> 3
A28: NIST AI RMF
A29: Group | B29: Total items | C29: Not started | D29: In progress | E29: Implemented | F29: Verified | G29: Not applicable | H29: % Complete (Impl.+Verified / applicable)
A30: NIST AI RMF - all items | B30: =SUM(C30:G30) -> 19 | C30: =COUNTIF('5 NIST AI RMF'!$J$4:$J$26,"Not started") -> 19 | D30: =COUNTIF('5 NIST AI RMF'!$J$4:$J$26,"In progress") -> 0 | E30: =COUNTIF('5 NIST AI RMF'!$J$4:$J$26,"Implemented") -> 0 | F30: =COUNTIF('5 NIST AI RMF'!$J$4:$J$26,"Verified") -> 0 | G30: =COUNTIF('5 NIST AI RMF'!$J$4:$J$26,"Not applicable") -> 0 | H30: =IFERROR((E30+F30)/(B30-G30),0) -> 0
A31: NIST AI RMF - CIA-security items | B31: =SUMPRODUCT(--(('5 NIST AI RMF'!D4:D26<>"")+('5 NIST AI RMF'!E4:E26<>"")+('5 NIST AI RMF'!F4:F26<>"")>0)) -> 6
A33: ISO/IEC 42005
A34: Group | B34: Total items | C34: Not started | D34: In progress | E34: Implemented | F34: Verified | G34: Not applicable | H34: % Complete (Impl.+Verified / applicable)
A35: ISO 42005 - all items | B35: =SUM(C35:G35) -> 21 | C35: =COUNTIF('6 ISO 42005 Impact Assessment'!$J$4:$J$28,"Not started") -> 21 | D35: =COUNTIF('6 ISO 42005 Impact Assessment'!$J$4:$J$28,"In progress") -> 0 | E35: =COUNTIF('6 ISO 42005 Impact Assessment'!$J$4:$J$28,"Implemented") -> 0 | F35: =COUNTIF('6 ISO 42005 Impact Assessment'!$J$4:$J$28,"Verified") -> 0 | G35: =COUNTIF('6 ISO 42005 Impact Assessment'!$J$4:$J$28,"Not applicable") -> 0 | H35: =IFERROR((E35+F35)/(B35-G35),0) -> 0
A36: ISO 42005 - CIA-security items | B36: =SUMPRODUCT(--(('6 ISO 42005 Impact Assessment'!D4:D28<>"")+('6 ISO 42005 Impact Assessment'!E4:E28<>"")+('6 ISO 42005 Impact Assessment'!F4:F28<>"")>0)) -> 3
A38: ISO/IEC 27001:2022
A39: Group | B39: Total items | C39: Not started | D39: In progress | E39: Implemented | F39: Verified | G39: Not applicable | H39: % Complete (Impl.+Verified / applicable)
A40: ISO 27001 - all items | B40: =SUM(C40:G40) -> 123 | C40: =COUNTIF('7 ISO 27001'!$J$4:$J$139,"Not started") -> 123 | D40: =COUNTIF('7 ISO 27001'!$J$4:$J$139,"In progress") -> 0 | E40: =COUNTIF('7 ISO 27001'!$J$4:$J$139,"Implemented") -> 0 | F40: =COUNTIF('7 ISO 27001'!$J$4:$J$139,"Verified") -> 0 | G40: =COUNTIF('7 ISO 27001'!$J$4:$J$139,"Not applicable") -> 0 | H40: =IFERROR((E40+F40)/(B40-G40),0) -> 0
A41: ISO 27001 - CIA-security items | B41: =SUMPRODUCT(--(('7 ISO 27001'!D4:D139<>"")+('7 ISO 27001'!E4:E139<>"")+('7 ISO 27001'!F4:F139<>"")>0)) -> 85
A43: ISO/IEC 17021-1
A44: Group | B44: Total items | C44: Not started | D44: In progress | E44: Implemented | F44: Verified | G44: Not applicable | H44: % Complete (Impl.+Verified / applicable)
A45: ISO 17021 - all items | B45: =SUM(C45:G45) -> 42 | C45: =COUNTIF('8 ISO 17021 Alignment'!$L$4:$L$52,"Not started") -> 42 | D45: =COUNTIF('8 ISO 17021 Alignment'!$L$4:$L$52,"In progress") -> 0 | E45: =COUNTIF('8 ISO 17021 Alignment'!$L$4:$L$52,"Implemented") -> 0 | F45: =COUNTIF('8 ISO 17021 Alignment'!$L$4:$L$52,"Verified") -> 0 | G45: =COUNTIF('8 ISO 17021 Alignment'!$L$4:$L$52,"Not applicable") -> 0 | H45: =IFERROR((E45+F45)/(B45-G45),0) -> 0
A46: ISO 17021 - CIA-security items | B46: =SUMPRODUCT(--(('8 ISO 17021 Alignment'!F4:F52<>"")+('8 ISO 17021 Alignment'!G4:G52<>"")+('8 ISO 17021 Alignment'!H4:H52<>"")>0)) -> 11
A48: GDPR
A49: Group | B49: Total items | C49: Not started | D49: In progress | E49: Implemented | F49: Verified | G49: Not applicable | H49: % Complete (Impl.+Verified / applicable)
...

Sheet Read Me
A1: ISO/IEC 42001:2023 (AIMS) - CIA-Security vs Remaining Controls Checklist
A3: Scope: Clauses 4-10 (32 items) and Annex A (38 controls), segregated into two working sheets so security effort is clearly separated from the rest.
A4: Sheet 1 - CIA-Security Controls: items whose primary purpose is to protect the Confidentiality, Integrity or Availability of information/AI assets (data, models, code, infrastructure, logs, documented information). Columns C / I / A show which property each item protects. These need security ownership (CISO/security architecture) and technical evidence.
A5: Sheet 2 - Non-CIA (Other) Controls: governance, leadership, risk planning (general), impact assessment on individuals/society, fairness/ethics, transparency, competence, documentation, performance evaluation, improvement. Owned by AI governance, compliance, legal, HR, product. Column F notes where an item still enables security indirectly.
A6: Judgement rule: an item is CIA-security only if a failure of the requirement would directly expose AI assets to unauthorized access/disclosure (C), unauthorized alteration/poisoning/loss of trustworthiness (I), or loss of access/service (A). Privacy/lawfulness of data use is treated as governance unless the requirement itself is about protecting the data.
A7: The classification is expert judgement for audit planning, not part of the standard. Adjust to your risk assessment; move a row between sheets if your context requires.
A8: How to use: set 'Applicable (SoA)', track 'Status', assign Owner, note gaps. Clauses 4-10 are mandatory; Annex A exclusions need justification (clause 6.1.3). Requirement text is a condensed paraphrase - verify against ISO/IEC 42001:2023 (Annex B guidance).
A9: Counts: CIA-security = 18 items; Non-CIA = 52 items; total = 70.
A10: Tab 3 - EU AI Act: 34 articles/annex items relevant to security governance and high-risk AI compliance, of which 12 are marked CIA-security (mainly Art.15 Accuracy/Robustness/Cybersecurity, Art.9 risk management, Art.10 data governance, Art.12/19 logging, Art.26 deployer logging/monitoring, Art.55 GPAI systemic-risk cybersecurity, Art.72 post-market monitoring, Art.73 incident reporting).
A11: Tab 4 - OECD AI Principles (updated May 2024): 14 items across the 5 values-based principles, 5 policy recommendations and 4 update focus areas, of which 3 are marked CIA-security (mainly 1.4 Robustness, security and safety, plus 1.2 privacy and 1.5 accountability/traceability).
A12: Tab 5 - NIST AI RMF 1.0 (NIST.AI.100-1): 19 categories across GOVERN (6), MAP (5), MEASURE (4) and MANAGE (4) - the framework's full structure is 19 categories / 72 subcategories; this tab tracks at category level. 6 categories are marked CIA-security (Govern 6, Map 4 and Manage 3 - third-party/supply-chain risk; Measure 2 - secure & resilient testing; Measure 3 - risk tracking/monitoring; Manage 4 - incident response and recovery). Suggested actions are condensed from the AI RMF Playbook; verify against NIST.AI.100-1 and the Playbook for subcategory-level detail.
A13: Tab 6 - ISO/IEC 42005:2025 (AI System Impact Assessment guidance): 21 items covering Clause 5 (developing/implementing the AISIA process), Clause 6 (documenting the AISIA) and the informative annexes (incl. Annex A linking to ISO/IEC 42001 clauses 6.1.2/6.1.4/A.5, Annex B linking to ISO/IEC 23894, and the Annex E AISIA template). 3 items are marked CIA-security (impact identification covering security-related harms, integrity of assessment records, confidentiality/access control of records). ISO/IEC 42005 is a guidance document (not a certifiable requirements standard); Clause 5/6 sub-points here are a thematic breakdown of its content, not verbatim numbered subclauses - verify structure and wording against the purchased standard.
... A31: Tab 22 - MITRE ATLAS (Adversarial Threat Landscape for Artificial-Intelligence Systems): 18 items covering all 16 current ATLAS tactics (Reconnaissance, Resource Development, Initial Access, AI Model Access, Execution, Persistence, Privilege Escalation, Defense Evasion, Credential Access, Discovery, Lateral Movement, Collection, AI Attack Staging, Command and Control, Exfiltration, Impact), verified current as of October 2026. ATLAS mirrors MITRE ATT&CK's structure (tactics as adversary objectives/columns, techniques as methods/rows beneath each, linked to real-world case studies) but is AI/ML-specific; 'AI Model Access' and 'AI Attack Staging' are the two tactics with no direct ATT&CK equivalent and carry the AI-native logic. This tab is deliberately at tactic level (16 rows) rather than enumerating the full ~100+ techniques/sub-techniques, to match the granularity used elsewhere in this workbook - for hands-on red-teaming or detection-engineering work, consult the live matrix at atlas.mitre.org for the current technique list under each tactic, since ATLAS is actively updated (recent releases have added agentic-AI and multi-agent techniques at a fast pace). 15 items are marked CIA-security (Resource Development is the one exception, being purely attacker-side preparation with no direct impact on the target yet). IMPORTANT: ATLAS is a threat-intelligence and red-team/detection reference, not a certifiable compliance checklist like the other standards in this workbook - use it to structure red-team scope and SOC detection use cases, and cross-walk it against your own AI architecture rather than treating every tactic as a control to 'complete'. It complements Tab 10 (OWASP LLM Top 10, which gives the vulnerability-centric view) and Tab 21 (ISO/IEC 27090, which gives the ISO-governance threat view) - ATLAS adds the adversary's full attack-lifecycle perspective with documented real-world case studies behind each technique.

Sheet 1 CIA-Security Controls
A1: ISO/IEC 42001:2023 - Items with Confidentiality / Integrity / Availability involvement (security needed)
A3: Ref | B3: Source | C3: Title | D3: Security requirement | E3: C | F3: I | G3: A | H3: Why CIA is involved / what must be protected | I3: ISO 27001:2022 cross-ref | J3: Evidence to verify | K3: Applicable (SoA) | L3: Status | M3: Owner | N3: Notes / Gap
A4: Clauses 4-10
A5: 6.1.2 | B5: Clause | C5: AI risk assessment | D5: Define and apply an AI risk assessment process: risk criteria, consistent/valid/comparable results, identify risks, analyse potential consequences and likelihood, evaluate and prioritise; retain documented information. | E5: ● | F5: ● | G5: ● | H5: Cover AI-specific threats: data poisoning, model theft/inversion, adversarial inputs, prompt injection, supply chain. | I5: 6.1.2, A.5.7 | J5: AI risk methodology, AI risk register and assessments | K5: Yes | L5: Not started
A6: 6.1.3 | B6: Clause | C6: AI risk treatment | D6: Define AI risk treatment process: select options, determine necessary controls (compare with Annex A), produce Statement of Applicability with justification, formulate treatment plan, obtain approval and residual risk acceptance. | E6: ● | F6: ● | G6: ● | H6: Select security controls; compare with ISO 27001 Annex A in SoA. | I6: 6.1.3 | J6: AI risk treatment plan, SoA, residual risk sign-off | K6: Yes | L6: Not started
A7: 7.5.3 | B7: Clause | C7: Control of documented information | D7: Control availability, protection, distribution, access, storage, version control, retention and disposition; control external-origin documents. | E7: ● | F7: ● | G7: ● | H7: Protect confidentiality/integrity/availability of AIMS documents (models, data docs). | I7: 7.5.3, A.5.33 | J7: DMS configuration, retention rules | K7: Yes | L7: Not started
A8: 8.2 | B8: Clause | C8: AI risk assessment | D8: Perform AI risk assessments at planned intervals or when significant changes are proposed/occur; retain results. | E8: ● | F8: ● | G8: ● | H8: Periodic AI security risk assessment. | I8: 8.2 | J8: Dated risk assessment outputs | K8: Yes | L8: Not started
A9: 8.3 | B9: Clause | C9: AI risk treatment | D9: Implement the AI risk treatment plan and retain results of treatment. | E9: ● | F9: ● | G9: ● | H9: Implement security risk treatment plan. | I9: 8.3 | J9: Treatment plan status, closure evidence | K9: Yes | L9: Not started
A10: Annex A controls
A11: A.4.4 | B11: Annex A | C11: Tooling resources | D11: Document tooling resources used for the AI system (algorithms, models, libraries, frameworks, MLOps). | E11: ● | F11: ● | G11: ● | H11: Secure AI libraries, frameworks, model artifacts, MLOps pipeline. | I11: A.5.21, A.8.9, A.8.19, A.8.30 | J11: Tooling/model registry, SBOM/MLBOM | K11: Yes | L11: Not started
A12: A.4.5 | B12: Annex A | C12: System and computing resources | D12: Document system and computing resources used (hardware, cloud, compute, storage). | E12: ● | F12: ● | G12: ● | H12: Secure compute, cloud and GPU/infrastructure. | I12: A.5.23, A.8.6, A.8.9, A.8.20, A.7.8 | J12: Infrastructure/compute inventory | K12: Yes | L12: Not started
A13: A.6.1.3 | B13: Annex A | C13: Processes for responsible AI system design and development | D13: Define and document specific processes for responsible design and development of AI systems. | E13: ● | F13: ● | G13: ● | H13: Secure-by-design AI SDLC. | I13: A.8.25, A.8.27, A.8.28 | J13: AI SDLC/MLOps procedures, gates | K13: Yes | L13: Not started
A14: A.6.2.2 | B14: Annex A | C14: AI system requirements and specification | D14: Specify and document requirements for new AI systems or material enhancements. | E14: ● | F14: ● | G14: ● | H14: Security requirements and threat modelling for AI. | I14: A.8.26, A.8.27, A.5.8 | J14: Requirements specs incl. risk/impact inputs | K14: Yes | L14: Not started
A15: A.6.2.4 | B15: Annex A | C15: AI system verification and validation | D15: Define and document verification/validation measures and criteria (performance, bias, robustness, security testing). | E15: ● | F15: ● | G15: ● | H15: Adversarial/red-team testing, robustness, vulnerability scanning. | I15: A.8.29, A.8.8, A.8.33 | J15: Test plans, V&V reports, acceptance criteria | K15: Yes | L15: Not started
A16: A.6.2.5 | B16: Annex A | C16: AI system deployment | D16: Document a deployment plan and ensure appropriate requirements are met before deployment. | F16: ● | G16: ● | H16: Secure release, change approval, environment separation. | I16: A.8.32, A.8.31, A.8.9 | J16: Deployment plan, go-live approval | K16: Yes | L16: Not started
A17: A.6.2.6 | B17: Annex A | C17: AI system operation and monitoring | D17: Define and document elements for ongoing operation: system and performance monitoring, repairs, updates and support. | E17: ● | F17: ● | G17: ● | H17: Drift/abuse monitoring, patching, incident detection. | I17: A.8.15, A.8.16, A.8.8, A.5.25 | J17: Monitoring dashboards, drift/performance alerts, update procedures | K17: Yes | L17: Not started
A18: A.6.2.8 | B18: Annex A | C18: AI system recording of event logs | D18: Determine at which phases of the life cycle event logs should be enabled, at minimum when the system is in use. | E18: ● | F18: ● | H18: Tamper-resistant logs, time sync, retention. | I18: A.8.15, A.8.16, A.8.17 | J18: Logging standard, log samples, retention | K18: Yes | L18: Not started
A19: A.7.4 | B19: Annex A | C19: Quality of data for AI systems | D19: Define and document data quality requirements and ensure data used meets them. | F19: ● | H19: Data integrity; defence against poisoning. | I19: A.5.12 | J19: Data quality criteria and check results | K19: Yes | L19: Not started
A20: A.7.5 | B20: Annex A | C20: Data provenance | D20: Define and document a process for recording provenance of data (and its updates) throughout the life cycle. | F20: ● | H20: Traceability and integrity of data lineage. | I20: A.5.9, A.8.15, A.5.33 | J20: Lineage/provenance records | K20: Yes | L20: Not started
A21: A.8.4 | B21: Annex A | C21: Communication of incidents | D21: Determine and document a plan for communicating incidents to users and other interested parties (incl. regulators). | E21: ● | F21: ● | G21: ● | H21: Incident notification to users/regulators. | I21: A.5.24, A.5.26, A.5.5 | J21: AI incident communication plan | K21: Yes | L21: Not started
A22: A.10.2 | B22: Annex A | C22: Allocating responsibilities | D22: Ensure responsibilities within the AI life cycle are allocated between the organization, partners, suppliers, customers and third parties. | E22: ● | F22: ● | G22: ● | H22: Shared-responsibility for security across parties. | I22: A.5.19, A.5.20, A.5.23 | J22: Responsibility matrix, contracts | K22: Yes | L22: Not started
A23: A.10.3 | B23: Annex A | C23: Suppliers | D23: Establish a process to ensure supplier services, products or materials align with the organization's responsible AI approach. | E23: ● | F23: ● | G23: ● | H23: Supplier security due diligence, contracts, monitoring. | I23: A.5.19-A.5.22 | J23: Supplier AI due-diligence, contract clauses | K23: Yes | L23: Not started

Sheet 2 Non-CIA (Other) Controls
A1: ISO/IEC 42001:2023 - Remaining items (governance, ethics, societal, privacy, documentation - no direct CIA protection)
A3: Ref | B3: Source | C3: Title | D3: Requirement | E3: Nature of requirement | F3: Security enabler link (indirect, if any) | G3: Evidence to verify | H3: Applicable (SoA) | I3: Status | J3: Owner | K3: Notes / Gap
A4: Clauses 4-10
A5: 4.1 | B5: Clause | C5: Understanding the organization and its context | D5: Determine external/internal issues relevant to the AIMS purpose and to achieving its intended results, incl. the organization's role(s) (provider, producer, user, etc.) and applicable AI-related climate/regulatory factors. | E5: Governance & context | F5: Include threat landscape/AI attack surface in context. (4.1) | G5: Context analysis, AI role determination, issue register | H5: Yes | I5: Not started
A6: 4.2 | B6: Clause | C6: Understanding the needs and expectations of interested parties | D6: Identify interested parties relevant to the AIMS, their requirements (incl. legal/regulatory, e.g. EU AI Act, PDPPL) and which will be addressed through the AIMS. | E6: Governance & context | F6: Security, privacy and regulatory requirements of stakeholders. (4.2) | G6: Stakeholder register, AI regulatory/contractual requirements register | H6: Yes | I6: Not started
A7: 4.3 | B7: Clause | C7: Determining the scope of the AI management system | D7: Determine and document AIMS boundaries and applicability, considering 4.1, 4.2 and the AI systems in scope. | E7: Governance & context | F7: Scope should cover AI assets and their security boundaries. (4.3) | G7: Approved AIMS scope statement, AI system list | H7: Yes | I7: Not started
A8: 4.4 | B8: Clause | C8: AI management system | D8: Establish, implement, maintain and continually improve the AIMS, including needed processes and their interactions. | E8: Governance & context | F8: Integrate AIMS with the ISMS. (4.4) | G8: AIMS process map/manual | H8: Yes | I8: Not started
A9: 5.1 | B9: Clause | C9: Leadership and commitment | D9: Top management demonstrates commitment: AI policy and objectives aligned to strategy, AIMS integrated into processes, resources provided, importance of effective AI management communicated, outcomes ensured, improvement promoted. | E9: Leadership & governance | F9: Leadership commitment to security within AI governance. (5.1) | G9: Management minutes, sponsorship, budget approvals | H9: Yes | I9: Not started
A10: 5.2 | B10: Clause | C10: AI policy | D10: Establish, document, communicate and make available an AI policy appropriate to the organization's purpose, providing a framework for AI objectives, committing to applicable requirements and continual improvement; consistent with other policies. | E10: Leadership & governance | F10: AI policy must align with the information security policy. (5.2, A.5.1) | G10: Approved AI policy, communication records | H10: Yes | I10: Not started
A11: 5.3 | B11: Clause | C11: Roles, responsibilities and authorities | D11: Assign and communicate AIMS roles, incl. responsibility for conformity to the standard and reporting AIMS performance to top management. | E11: Leadership & governance | F11: Security roles for AI systems. (5.3, A.5.2) | G11: RACI, AI governance charter, appointment records | H11: Yes | I11: Not started
A12: 6.1.1 | B12: Clause | C12: Actions to address risks and opportunities - General | D12: Determine risks and opportunities to give assurance the AIMS achieves outcomes, prevents/reduces undesired effects, and enables improvement; plan actions and evaluate effectiveness. | E12: Risk & planning (general) | F12: Security risks/opportunities feed AIMS planning. (6.1.1) | G12: Risk & opportunity register | H12: Yes | I12: Not started
A13: 6.1.4 | B13: Clause | C13: AI system impact assessment | D13: Define a process to assess potential consequences of AI systems on individuals, groups and society through their life cycle; document and retain results. | E13: Impact assessment (individual / societal) | F13: Impacts from security failures (privacy breach, safety harm). (A.5.34) | G13: Impact assessment procedure and completed assessments | H13: Yes | I13: Not started
A14: 6.2 | B14: Clause | C14: AI objectives and planning to achieve them | D14: Establish measurable AI objectives at relevant functions/levels, consistent with the AI policy; plan what, resources, owner, deadline and evaluation. | E14: Risk & planning (general) | F14: Set security/robustness objectives for AI systems. (6.2) | G14: AI objectives register, KPIs | H14: Yes | I14: Not started
A15: 6.3 | B15: Clause | C15: Planning of changes | D15: Carry out AIMS changes in a planned manner when a need for change is determined. | E15: Risk & planning (general) | F15: Security review of AIMS/AI system changes. (6.3, A.8.32) | G15: Change records, impact analysis | H15: Yes | I15: Not started
A16: 7.1 | B16: Clause | C16: Resources | D16: Determine and provide resources needed to establish, implement, maintain and improve the AIMS. | E16: Support: resources, competence, communication | F16: None | G16: Resource plans, budget | H16: Yes | I16: Not started
... A31: 10.2 | B31: Clause | C31: Nonconformity and corrective action | D31: React to NCs, evaluate need to eliminate causes, implement and review corrective action effectiveness, update AIMS; retain evidence. | E31: Improvement | F31: Corrective action after security incidents/NCs. (10.2, A.5.27) | G31: NC/CAPA log, root-cause analyses | H31: Yes | I31: Not started
A32: Annex A controls
A33: A.2.2 | B33: Annex A | C33: AI policy | D33: Document a policy for the development or use of AI systems. | E33: AI policy & alignment | F33: Reference security requirements in AI policy. (A.5.1) | G33: Approved AI policy | H33: Yes | I33: Not started
A34: A.2.3 | B34: Annex A | C34: Alignment with other organizational policies | D34: Determine where other policies (security, privacy, quality, safety, etc.) are affected by or apply to AI objectives, and align them. | E34: AI policy & alignment | F34: Align with information security and privacy policies. (A.5.1) | G34: Policy mapping/crosswalk | H34: Yes | I34: Not started
A35: A.2.4 | B35: Annex A | C35: Review of the AI policy | D35: Review the AI policy at planned intervals or on significant change to ensure continuing suitability, adequacy and effectiveness. | E35: AI policy & alignment | F35: None | G35: Review records, version history | H35: Yes | I35: Not started
A36: A.3.2 | B36: Annex A | C36: AI roles and responsibilities | D36: Define and allocate AI roles and responsibilities per organizational needs. | E36: Organization & accountability | F36: Security accountability for AI systems. (A.5.2, A.5.4) | G36: AI governance roles, RACI, committee charter | H36: Yes | I36: Not started
A37: A.3.3 | B37: Annex A | C37: Reporting of concerns | D37: Define and put in place a process to report concerns about the organization's role with respect to an AI system throughout its life cycle. | E37: Organization & accountability | F37: Channel for security concerns. (A.6.8, A.5.26) | G37: Whistleblowing/concern channel, case records | H37: Yes | I37: Not started
A38: A.4.2 | B38: Annex A | C38: Resource documentation | D38: Identify and document relevant resources required for each AI system life-cycle stage and other AI-related activities, to understand and address risks/impacts. | E38: AI resource management | F38: Asset inventory of AI resources. (A.5.9) | G38: AI resource inventory | H38: Yes | I38: Not started
A39: A.4.3 | B39: Annex A | C39: Data resources | D39: Document information about data resources used for the AI system. | E39: AI resource management | F39: Classification and protection of datasets. (A.5.9, A.5.12) | G39: Dataset inventory, data catalogue | H39: Yes | I39: Not started
A40: A.4.6 | B40: Annex A | C40: Human resources | D40: Document human resources and their competences for development, deployment, operation, change management, maintenance, transfer and decommissioning, and verification and integration of the AI system. | E40: AI resource management | F40: Vetted, trained AI personnel. (A.6.1, A.6.3) | G40: Competence matrix, staffing records | H40: Yes | I40: Not started
A41: A.5.2 | B41: Annex A | C41: AI system impact assessment process | D41: Establish a process to assess potential consequences for individuals, groups and society from the AI system throughout its life cycle. | E41: Impact assessment (individual / societal) | F41: Include security and privacy harms in impact process. (A.5.34) | G41: Impact assessment procedure and triggers | H41: Yes | I41: Not started
A42: A.5.3 | B42: Annex A | C42: Documentation of AI system impact assessments | D42: Document results of impact assessments and retain for a defined period. | E42: Impact assessment (individual / societal) | F42: None | G42: Assessment records and retention rules | H42: Yes | I42: Not started
A43: A.5.4 | B43: Annex A | C43: Assessing AI system impact on individuals or groups of individuals | D43: Assess and document impacts on individuals/groups throughout the life cycle (e.g. fairness, privacy, safety, rights). | E43: Impact assessment (individual / societal) | F43: Privacy/safety impacts on individuals. (A.5.34) | G43: Individual/group impact analyses, fairness testing | H43: Yes | I43: Not started
A44: A.5.5 | B44: Annex A | C44: Assessing societal impacts of AI systems | D44: Assess and document societal impacts (e.g. environment, economy, culture, public health, misinformation) throughout the life cycle. | E44: Impact assessment (individual / societal) | F44: None | G44: Societal impact analyses | H44: Yes | I44: Not started
... A57: A.10.4 | B57: Annex A | C57: Customers | D57: Ensure the organization's responsible AI approach considers customer expectations and needs. | E57: Customer relationships | F57: Customer security and data requirements. (A.5.20, A.5.34) | G57: Customer requirements, feedback, contractual commitments | H57: Yes | I57: Not started

Sheet 3 EU AI Act
A1: EU AI Act (Regulation (EU) 2024/1689) - Clause Checklist, with Role Responsibilities and CIA-Security Marking
A2: Role Legend (Article 3 definitions)
A3: Role | B3: Definition (Art.3) | C3: Key responsibilities (summary)
A4: Provider | B4: Develops an AI system or GPAI model (or has one developed) and places it on the market / puts it into service under its own name or trademark, for payment or free of charge. | C4: Bears the primary compliance burden: classification, risk management, technical documentation, conformity assessment, CE marking, registration, post-market monitoring, incident reporting.
A5: Deployer | B5: Uses an AI system under its own authority, except where used in the course of a purely personal, non-professional activity. | C5: Must use the system per the provider's instructions, assign competent human oversight, monitor operation, keep logs it controls, and report risks/incidents it becomes aware of.
A6: Authorised Representative | B6: A person established in the EU, holding a written mandate from a non-EU provider, to act on the provider's behalf for specified obligations. | C6: Carries out mandated tasks (conformity documentation, registration, cooperation with authorities) on behalf of a non-EU provider.
A7: Importer | B7: A person established in the EU that places on the EU market an AI system bearing the name or trademark of a person established outside the EU. | C7: Verifies conformity assessment, documentation and CE marking before placing the system on the market; ensures safe storage/transport.
A8: Distributor | B8: A person in the supply chain, other than the provider or importer, that makes an AI system available on the EU market. | C8: Verifies CE marking and documentation before distribution; must not distribute non-conforming systems; takes corrective action if non-conformity is found.
A9: Product Manufacturer | B9: Places an AI system on the market or into service together with its own product, under its own name or trademark. | C9: Takes on provider-equivalent obligations for the AI system embedded in its product.
A10: Operator (umbrella term) | B10: Collective term covering Provider, Deployer, Authorised Representative, Importer, Distributor and Product Manufacturer. | C10: Used where an obligation (e.g. Art.5 prohibited practices, Art.99 penalties) applies across all roles rather than one specifically.
A11: GPAI Model Provider | B11: A Provider specifically of a general-purpose AI model; a further 'systemic risk' tier applies above a compute/capability threshold (Art.51). | C11: Technical documentation, downstream-provider information, copyright policy, training-content summary (Art.53); systemic-risk providers add model evaluation, adversarial testing and cybersecurity protection (Art.55).
A13: Article/Annex | B13: Title | C13: Applicable Role(s) & Responsibilities | D13: Requirement | E13: C | F13: I | G13: A | H13: Security note / why CIA is involved | I13: Evidence to verify | J13: Applicable | K13: Status | L13: Owner | M13: Notes / Gap
A14: Chapter I | B14: General provisions
A15: Art.2 | B15: Scope | C15: Operator (umbrella term covering Provider, Deployer, Importer, Distributor, Authorised Representative, Product Manufacturer) - this article determines which role(s) an organization holds and therefore which obligations apply. | D15: Determine applicability: providers, deployers, importers, distributors and product manufacturers placing AI systems/GPAI models on the EU market or whose output is used in the EU. | H15: None - governance/process requirement without a direct CIA-protection function. | I15: Applicability assessment | J15: Yes | K15: Not started
A16: Art.3 | B16: Definitions | C16: All roles - this article is the source of the role definitions themselves (see the Role Legend above). | D16: Apply the Act's definitions (AI system, provider, deployer, high-risk, GPAI model, serious incident, etc.) consistently across governance documents. | H16: None - governance/process requirement without a direct CIA-protection function. | I16: Glossary/definitions mapping | J16: Yes | K16: Not started
A17: Art.4 | B17: AI literacy | C17: Provider and Deployer - both must ensure their own staff (and others acting on their behalf) have sufficient AI literacy. | D17: Take measures to ensure sufficient AI literacy of staff and others dealing with AI systems on the organization's behalf, considering their technical knowledge, experience and context of use. | H17: None - governance/process requirement without a direct CIA-protection function. | I17: AI literacy programme, training records | J17: Yes | K17: Not started
A18: Chapter II | B18: Prohibited AI practices
A19: Art.5 | B19: Prohibited AI practices | C19: Provider (must not place on market/put into service) and Deployer (must not use) - the prohibition binds both roles independently. | D19: Do not place on the market, put into service or use AI systems for prohibited practices: subliminal/manipulative techniques causing harm, exploitation of vulnerabilities, social scoring, real-time remote biometric ID in public for law enforcement (subject to exceptions), biometric categorisation inferring sensitive attributes, emotion recognition in workplace/education (with exceptions), untargeted facial-image scraping, individual crime-risk prediction based solely on profiling. | E19: ● | H19: Emotion recognition, biometric categorisation and scraping controls overlap with data confidentiality and consent safeguards. | I19: Prohibited-use screening/legal review, use-case register | J19: Yes | K19: Not started
A20: Chapter III S1 | B20: High-risk classification
A21: Art.6 | B21: Classification rules for high-risk AI systems | C21: Provider - responsible for classifying their own AI system before placing it on the market or putting it into service. | D21: Determine whether an AI system is high-risk: safety component of a regulated product (Annex I) or use case listed in Annex III, with a narrow self-assessment exemption where risk is not significant. | H21: None - governance/process requirement without a direct CIA-protection function. | I21: Classification/risk-tier assessment per system | J21: Yes | K21: Not started
A22: Art.7 | B22: Amendments to Annex III | C22: Provider - must monitor for classification-list changes affecting systems it has already placed on the market. | D22: Monitor Commission updates to the high-risk use-case list (Annex III) and re-assess systems accordingly. | H22: None - governance/process requirement without a direct CIA-protection function. | I22: Regulatory watch process | J22: Yes | K22: Not started
A23: Chapter III S2 | B23: Requirements for high-risk AI systems
A24: Art.8 | B24: Compliance with the requirements | C24: Provider - primary and direct responsibility for meeting Articles 9-15 across the system's lifecycle. | D24: Ensure high-risk AI systems comply with Articles 9-15 throughout their lifecycle, considering intended purpose and generally acknowledged state of the art. | H24: None - governance/process requirement without a direct CIA-protection function. | I24: Compliance programme covering Art.9-15 | J24: Yes | K24: Not started
A25: Art.9 | B25: Risk management system | C25: Provider - must establish and maintain the risk management system for the high-risk AI system. | D25: Establish, implement, document and maintain a continuous risk management process across the lifecycle: identify, analyse, estimate and evaluate known/foreseeable risks, adopt mitigation measures, and test. | F25: ● | H25: Risk management must cover security/adversarial risks alongside safety and fundamental-rights risks. | I25: AI risk management file, test reports | J25: Yes | K25: Not started
A26: Art.10 | B26: Data and data governance | C26: Provider - responsible for the data governance practices applied during development of the high-risk AI system. | D26: Apply data governance practices to training/validation/testing data: relevant design choices, provenance, collection, bias examination, gaps identification, and appropriate quality/representativeness; protect data appropriately. | E26: ● | F26: ● | H26: Poor data governance is a direct integrity risk (poisoning, bias) and can expose confidential data if provenance/access is not controlled. | I26: Data governance procedure, dataset documentation | J26: Yes | K26: Not started
A27: Art.11 | B27: Technical documentation | C27: Provider - must draw up and maintain the technical documentation per Annex IV. | D27: Draw up technical documentation before placing on the market/putting into service and keep it up to date, per Annex IV (system description, design, development, risk management, performance, changes). | H27: None - governance/process requirement without a direct CIA-protection function. | I27: Technical documentation file | J27: Yes | K27: Not started
A28: Art.12 | B28: Record-keeping (logging) | C28: Provider - must design the logging capability into the system; Deployer - relies on and operates these logs during use (see Art.26). | D28: Design high-risk AI systems with capability for automatic logging of events over the system's lifetime to ensure traceability appropriate to intended purpose. | F28: ● | G28: ● | H28: Tamper-evident, available logs are needed for traceability and incident investigation. | I28: Logging design spec, log retention records | J28: Yes | K28: Not started
A29: Art.13 | B29: Transparency and provision of information to deployers | C29: Provider - must design for transparency and supply instructions for use; Deployer - is the recipient of this information and relies on it for compliant use. | D29: Design systems to be sufficiently transparent for deployers to interpret output and use appropriately; provide instructions for use with required content (identity, characteristics, performance, known limitations, human oversight measures, expected lifetime and maintenance). | H29: None - governance/process requirement without a direct CIA-protection function. | I29: Instructions for use, transparency documentation | J29: Yes | K29: Not started
A30: Art.14 | B30: Human oversight | C30: Provider - must design the human-oversight interface/tools into the system; Deployer - must actually assign competent human oversight during use (see Art.26). | D30: Design high-risk AI systems, including appropriate human-machine interface tools, to be effectively overseen by natural persons during use, able to understand, monitor and intervene (incl. stop/override). | H30: None - governance/process requirement without a direct CIA-protection function. | I30: Human oversight design, operator training | J30: Yes | K30: Not started
A31: Art.15 | B31: Accuracy, robustness and cybersecurity | C31: Provider - sole responsibility for designing and testing accuracy, robustness and cybersecurity into the system. | D31: Design and develop high-risk AI systems to achieve appropriate levels of accuracy, robustness and cybersecurity, perform consistently, and be resilient to errors, faults, inconsistencies, and attempts by unauthorised third parties to exploit vulnerabilities (data poisoning, adversarial examples, model evasion, confidentiality attacks), with technical redundancy/back-up where relevant. | E31: ● | F31: ● | G31: ● | H31: Direct cybersecurity obligation: protect against attacks on confidentiality (model/data extraction), integrity (poisoning, adversarial manipulation) and availability (denial of service, faults). | I31: Robustness/security test reports, resilience measures, cybersecurity controls | J31: Yes | K31: Not started
A32: Chapter III S3 | B32: Provider/deployer obligations
A33: Art.16 | B33: Obligations of providers of high-risk AI systems | C33: Provider - this article consolidates the full set of provider-specific obligations. | D33: Ensure conformity, have quality management system, keep documentation/logs, undergo conformity assessment, draw up EU declaration of conformity, affix CE marking, register system, take corrective action, cooperate with authorities. | H33: None - governance/process requirement without a direct CIA-protection function. | I33: Conformity file, CE marking, registration | J33: Yes | K33: Not started
A34: Art.17 | B34: Quality management system | C34: Provider - must establish and maintain the QMS. | D34: Put in place a quality management system documenting strategy for compliance, design control, data management, risk management, post-market monitoring, incident reporting, resource management, and an accountability framework. | H34: None - governance/process requirement without a direct CIA-protection function. | I34: QMS documentation | J34: Yes | K34: Not started
A35: Art.18 | B35: Documentation keeping | C35: Provider - the 10-year document retention duty rests with the provider. | D35: Keep technical documentation, QMS documentation, conformity assessment and EU declaration of conformity documentation for 10 years after placing on the market. | H35: None - governance/process requirement without a direct CIA-protection function. | I35: Document retention register | J35: Yes | K35: Not started
A36: Art.19 | B36: Automatically generated logs | C36: Provider - retains logs that are under its control (contrast with Art.26, where the Deployer retains logs under its own control). | D36: Keep the logs automatically generated by the high-risk AI system, to the extent they are under the provider's control, for a period appropriate to the intended purpose (at least 6 months unless otherwise provided). | F36: ● | G36: ● | H36: Preserving log integrity and availability for the retention period. | I36: Log retention policy and records | J36: Yes | K36: Not started
A37: Art.20 | B37: Corrective actions and duty of information | C37: Provider - must act and must notify Distributors, Deployers, the Authorised Representative and authorities as relevant. | D37: Take corrective actions or withdraw/recall a non-conforming system; inform distributors, deployers, authorised representative and, where relevant, authorities of the non-conformity and actions taken. | H37: None - governance/process requirement without a direct CIA-protection function. | I37: Corrective action procedure, notifications | J37: Yes | K37: Not started
A38: Art.21 | B38: Cooperation with competent authorities | C38: Provider - primary duty to cooperate; an Authorised Representative may also be approached where the provider is outside the EU. | D38: Provide competent authorities, on reasoned request, with information/documentation to demonstrate conformity, including access to automatically generated logs where relevant. | E38: ● | H38: Ensure controlled, confidential handling of information shared with authorities. | I38: Authority request-response log | J38: Yes | K38: Not started
A39: Art.22 | B39: Authorised representatives | C39: Authorised Representative - this article defines its role and mandated duties, appointed by a non-EU Provider. | D39: Non-EU providers appoint an EU authorised representative with a mandate covering conformity documentation, cooperation with authorities and registration duties. | H39: None - governance/process requirement without a direct CIA-protection function. | I39: Authorisation mandate | J39: Yes | K39: Not started
A40: Art.23 | B40: Obligations of importers | C40: Importer - this article sets out the Importer's specific verification and cooperation duties. | D40: Verify conformity assessment, documentation and CE marking before placing a system on the market; ensure storage/transport conditions do not jeopardise compliance; cooperate with authorities. | H40: None - governance/process requirement without a direct CIA-protection function. | I40: Import verification records | J40: Yes | K40: Not started
A41: Art.24 | B41: Obligations of distributors | C41: Distributor - this article sets out the Distributor's specific verification duties. | D41: Verify CE marking, documentation and conformity before making a system available; not make available if non-conforming; take corrective action if aware of non-conformity. | H41: None - governance/process requirement without a direct CIA-protection function. | I41: Distribution verification records | J41: Yes | K41: Not started
...

Sheet 4 OECD AI Principles
A1: OECD AI Principles (Recommendation of the Council on AI, updated May 2024) - Checklist, with CIA-Security Marking
A3: Ref | B3: Title | C3: Requirement | D3: C | E3: I | F3: A | G3: Security note / why CIA is involved | H3: Evidence to verify | I3: Applicable | J3: Status | K3: Owner | L3: Notes / Gap
A4: Section 1 | B4: Values-based principles for trustworthy AI
A5: 1.1 | B5: Inclusive growth, sustainable development and well-being | C5: AI actors should proactively engage in responsible stewardship of trustworthy AI for beneficial outcomes: augmenting human capabilities, advancing inclusion of underrepresented populations, reducing inequalities, and protecting the environment. | G5: None - governance/policy-level recommendation. | H5: Responsible-AI stewardship programme, sustainability/inclusion assessment | I5: Yes | J5: Not started
A6: 1.2 | B6: Human rights, democratic values and fairness (incl. privacy) | C6: Respect the rule of law, human rights and democratic values throughout the AI system lifecycle: non-discrimination, equality, freedom, dignity, autonomy, privacy and data protection, diversity, fairness, social justice and labour rights; implement mechanisms such as human oversight where needed. | D6: ● | G6: Privacy and data protection require confidentiality controls over personal data used by AI systems. | H6: Fairness/bias testing, privacy impact assessment, human oversight design | I6: Yes | J6: Not started
A7: 1.3 | B7: Transparency and explainability | C7: AI actors should provide meaningful information appropriate to context: to foster understanding, inform of AI interaction, enable those affected to understand outcomes, and enable those adversely affected to challenge outcomes based on plain and easy-to-understand information on factors and logic. | G7: None - governance/policy-level recommendation. | H7: Transparency notices, explainability documentation | I7: Yes | J7: Not started
A8: 1.4 | B8: Robustness, security and safety | C8: AI systems should function appropriately and not pose unreasonable safety/security risks throughout their lifecycle; traceability of datasets, processes and decisions; risk-based approach with continuous risk management (security, safety, bias) applied by AI actors to each phase; safeguards to ensure control can be reasserted (e.g. deactivation) when risks materialize. | D8: ● | E8: ● | F8: ● | G8: Directly requires security throughout the lifecycle: resilience against attacks, traceability (integrity), safe operation (availability/safety) and the ability to disable a malfunctioning or compromised system. | H8: Robustness/security testing, risk management process, traceability records, deactivation/kill-switch controls | I8: Yes | J8: Not started
A9: 1.5 | B9: Accountability | C9: AI actors should be accountable for the proper functioning of AI systems and respect of the principles, based on their roles, context, and consistent with the state of the art; enable traceability, incl. logging, to analyse outcomes and responses to inquiry; apply a systematic risk management approach to each phase of the lifecycle on an ongoing basis. | E9: ● | F9: ● | G9: Traceability/logging for accountability protects integrity of the record and requires availability of logs for inquiry. | H9: Accountability framework, role assignment, logging and audit trail | I9: Yes | J9: Not started
A10: Section 2 | B10: Policy recommendations for governments (organizational relevance)
A11: 2.1 | B11: Investing in AI research and development | C11: Foster investment in R&D, incl. long-term public investment and encouragement of private investment, to spur innovation in trustworthy AI. | G11: None - governance/policy-level recommendation. | H11: R&D investment plan / innovation budget | I11: Yes | J11: Not started
A12: 2.2 | B12: Fostering an inclusive AI-enabling ecosystem | C12: Foster accessible AI ecosystems with digital infrastructure, technologies, mechanisms to share data and knowledge responsibly and share metrics to measure AI research/development/deployment/growth. | G12: None - governance/policy-level recommendation. | H12: Ecosystem participation, data-sharing agreements | I12: Yes | J12: Not started
A13: 2.3 | B13: Shaping an enabling interoperable governance and policy environment | C13: Promote a policy environment that supports agile transition from R&D to deployment, incl. mechanisms such as regulatory sandboxes to experiment with AI safely, and work towards interoperable governance frameworks. | G13: None - governance/policy-level recommendation. | H13: Regulatory sandbox participation, policy/standards mapping | I13: Yes | J13: Not started
A14: 2.4 | B14: Building human capacity and preparing for labour-market transformation | C14: Equip people with skills for AI, support workers in transitioning jobs affected by AI, and ensure protection of labour rights. | G14: None - governance/policy-level recommendation. | H14: Workforce reskilling programme, labour-impact assessment | I14: Yes | J14: Not started
A15: 2.5 | B15: International co-operation for trustworthy AI | C15: Actively co-operate across borders and sectors to advance responsible stewardship of trustworthy AI, incl. common understanding of AI actor obligations, interoperable governance, standards and metrics. | G15: None - governance/policy-level recommendation. | H15: Participation in international AI governance initiatives | I15: Yes | J15: Not started
A16: Section 3 | B16: 2024 update focus areas
A17: 3.1 | B17: General-purpose and generative AI risks | C17: Address risks specific to general-purpose/foundation and generative AI models, incl. safety, misuse and information-integrity risks (e.g. disinformation, deepfakes). | G17: None - governance/policy-level recommendation. | H17: GPAI/genAI risk assessment, content provenance/watermarking | I17: Yes | J17: Not started
A18: 3.2 | B18: Environmental footprint | C18: Consider and where possible measure/reduce the environmental footprint (energy, compute, resources) of AI systems across their lifecycle. | G18: None - governance/policy-level recommendation. | H18: Environmental impact tracking (compute/energy use) | I18: Yes | J18: Not started
A19: 3.3 | B19: Intellectual property rights | C19: Respect intellectual property rights, incl. in relation to training data and generated content. | G19: None - governance/policy-level recommendation. | H19: IP due-diligence, training-data licensing review | I19: Yes | J19: Not started
A20: 3.4 | B20: Multi-stakeholder co-operation on risk | C20: Engage multiple stakeholders (government, industry, civil society, academia, technical community) to manage AI risks and information integrity collaboratively. | G20: None - governance/policy-level recommendation. | H20: Multi-stakeholder engagement records | I20: Yes | J20: Not started

Sheet 5 NIST AI RMF
A1: NIST AI RMF 1.0 (NIST.AI.100-1) - Category Checklist, with CIA-Security Marking
A3: Ref | B3: Category outcome | C3: Suggested action | D3: C | E3: I | F3: A | G3: Security note / why CIA is involved | H3: Evidence to verify | I3: Applicable | J3: Status | K3: Owner | L3: Notes / Gap
A4: GOVERN | B4: GOVERN - policy, accountability and culture (cross-cutting; applies to the whole organization)
A5: Govern 1 | B5: Policies, processes, procedures and practices for mapping, measuring and managing AI risk are established, documented and effectively implemented, reflecting organizational risk tolerance. | C5: Establish AI risk-management policies/processes covering legal/regulatory requirements, and review/update them regularly. | G5: None - governance/process-level outcome. | H5: AI risk management policy, process documentation, review log | I5: Yes | J5: Not started
A6: Govern 2 | B6: Accountability structures are in place so appropriate teams and individuals are empowered, responsible and trained for mapping, measuring and managing AI risks. | C6: Assign clear roles/responsibilities for AI risk management and provide training. | G6: None - governance/process-level outcome. | H6: RACI, role descriptions, training records | I6: Yes | J6: Not started
A7: Govern 3 | B7: Workforce diversity, equity, inclusion and accessibility processes are prioritized, and organizational risk management supported by a diverse team. | C7: Ensure diverse, multidisciplinary teams involved in AI risk decisions. | G7: None - governance/process-level outcome. | H7: Team composition records | I7: Yes | J7: Not started
A8: Govern 4 | B8: Organizational teams are committed to a culture that considers and communicates AI risk. | C8: Foster risk-aware culture, incl. incentives, policies for documenting risks/tradeoffs, and processes for flagging risks. | G8: None - governance/process-level outcome. | H8: Risk-culture initiatives, internal reporting mechanisms | I8: Yes | J8: Not started
A9: Govern 5 | B9: Processes are in place for robust engagement with relevant AI actors (incl. external stakeholders and end users). | C9: Establish mechanisms to solicit and incorporate feedback from relevant AI actors. | G9: None - governance/process-level outcome. | H9: Stakeholder engagement plan, feedback records | I9: Yes | J9: Not started
A10: Govern 6 | B10: Policies and procedures are in place to address AI risks and benefits arising from third-party software/data/systems and other supply-chain issues. | C10: Establish third-party/AI supply-chain risk management processes, incl. contracts and due diligence. | D10: ● | G10: Third-party/supply-chain AI components (models, data, libraries) are a confidentiality risk vector requiring security due diligence, similar to ISO 27001 supplier controls. | H10: Third-party AI risk policy, vendor due-diligence records, contract clauses | I10: Yes | J10: Not started
A11: MAP | B11: MAP - context, categorization and impacts (system-level)
A12: Map 1 | B12: Context is established and understood: intended purpose, business value, risk tolerances, requirements, and impacted stakeholders identified. | C12: Document AI system context: purpose, users, requirements (incl. legal/regulatory and security requirements). | G12: None - governance/process-level outcome. | H12: Context/use-case documentation | I12: Yes | J12: Not started
A13: Map 2 | B13: Categorization of the AI system is performed, incl. specific tasks and methods used to implement them. | C13: Categorize the AI system by task, method (e.g. classification, generative), and risk level. | G13: None - governance/process-level outcome. | H13: System categorization record | I13: Yes | J13: Not started
